Workbook

Sheet Bins
A1: Bin | B1: Zone | C1: Bin Label | D1: Part 1 | E1: Part 2 | F1: Part 3 | G1: Part 4 | H1: Part 5
A2: A1-1 | B2: Cart A – Small | C2: 1x1 Corner / 2x Wide 1x1 Offset | D2: 1x Wide, 1x1 Corner Connector | E2: 2x Wide, 1x1 Offset Corner Connector
A3: A1-2 | B3: Cart A – Small | C3: 1x Wide, 1x1 Offset Corner | D3: 1x Wide, 1x1 Offset Corner Connector
A4: A1-3 | B4: Cart A – Small | C4: 2x1 Corner / 2x1 Offset | D4: 2x Wide, 2x1 Corner Connector | E4: 2x Wide, 2x1 Offset Corner Connector
A5: A1-4 | B5: Cart A – Small | C5: 2x Wide, 1x2 Corner | D5: 2x Wide, 1x2 Corner Connector
A6: A1-5 | B6: Cart A – Small | C6: 2x Wide, 1x2 Offset Corner | D6: 2x Wide, 1x2 Offset Corner Connector
A7: A1-6 | B7: Cart A – Small | C7: 60° Omni 1x2 Corner | D7: 2x Wide, 60 Degree Omni 1x2 Corner Connector
A8: A1-7 | B8: Cart A – Small | C8: Small Chassis Corner Connector | D8: Small Chassis Corner Connector
A9: A1-8 | B9: Cart A – Small | C9: Large Chassis Corner Connector | D9: Large Chassis Corner Connector
A10: A2-1 | B10: Cart A – Small | C10: 2x Wide, 2x2 Corner | D10: 2x Wide, 2x2 Corner Connector
A11: A2-2 | B11: Cart A – Small | C11: 2x Wide, 2x2 Corner | D11: 2x Wide, 2x2 Corner Connector
A12: A2-3 | B12: Cart A – Small | C12: 2x Wide, 2x2 Offset Corner | D12: 2x Wide, 2x2 Offset Corner Connector
A13: A2-4 | B13: Cart A – Small | C13: 2x Wide, 3x2 Corner | D13: 2x Wide, 3x2 Corner Connector
A14: A2-5 | B14: Cart A – Small | C14: Double 1x2 / Double 2x2 Corner | D14: Double 2x Wide, 1x2 Corner Connector | E14: Double 2x Wide, 2x2 Corner Connector
A15: A2-6 | B15: Cart A – Small | C15: Double 2x2 Double Offset Corner | D15: Double 2x Wide, 2x2 Double Offset Corner Connector
A16: A2-7 | B16: Cart A – Small | C16: Triple 2x2 Corner | D16: Triple 2x Wide, 2x2 Corner Connector
A17: A2-8 | B17: Cart A – Small | C17: Triple 2x2 Corner | D17: Triple 2x Wide, 2x2 Corner Connector
A18: A3-1 | B18: Cart A – Small | C18: 1x1 Beam + 1x3 Beam | D18: 1x1 Beam | E18: 1x3 Beam
A19: A3-2 | B19: Cart A – Small | C19: 1x2 Beam + 1x5 Beam | D19: 1x2 Beam | E19: 1x5 Beam
A20: A3-3 | B20: Cart A – Small | C20: 1x4 Beam | D20: 1x4 Beam
A21: A3-4 | B21: Cart A – Small | C21: 1x6 Beam | D21: 1x6 Beam
A22: A3-5 | B22: Cart A – Small | C22: 1x8 Beam | D22: 1x8 Beam
A23: A3-6 | B23: Cart A – Small | C23: 1x8 Beam | D23: 1x8 Beam
A24: A3-7 | B24: Cart A – Small | C24: 1x10 Beam | D24: 1x10 Beam
A25: A3-8 | B25: Cart A – Small | C25: 1x10 Beam | D25: 1x10 Beam
A26: A4-1 | B26: Cart A – Small | C26: 2x2 Beam | D26: 2x2 Beam
A27: A4-2 | B27: Cart A – Small | C27: 2x4 Beam | D27: 2x4 Beam
A28: A4-3 | B28: Cart A – Small | C28: 2x4 Beam | D28: 2x4 Beam
A29: A4-4 | B29: Cart A – Small | C29: 2x6 Beam | D29: 2x6 Beam
A30: A4-5 | B30: Cart A – Small | C30: 2x6 Beam | D30: 2x6 Beam
A31: A4-6 | B31: Cart A – Small | C31: 2x7 Beam | D31: 2x7 Beam
... A34: A5-1 | B34: Cart A – Medium | C34: 2x10 Beam | D34: 2x10 Beam
A35: A5-2 | B35: Cart A – Medium | C35: 12-pitch beams: 1x12 + 2x12 | D35: 1x12 Beam | E35: 2x12 Beam
A36: A5-3 | B36: Cart A – Medium | C36: 16-pitch beams: 1x16 + 2x16 | D36: 1x16 Beam | E36: 2x16 Beam
A37: A5-4 | B37: Cart A – Medium | C37: 2x18 Beam | D37: 2x18 Beam
A38: A5-5 | B38: Cart A – Medium | C38: 2x20 Beam | D38: 2x20 Beam
A39: A6-1 | B39: Cart A – Medium | C39: Square Plates: 3x3 + 4x4 | D39: 3x3 Plate | E39: 4x4 Plate
A40: A6-2 | B40: Cart A – Medium | C40: 2x8 Smooth Panel + Pin Tool | D40: 2x8 Smooth Panel | E40: Pin Tool
A41: A6-3 | B41: Cart A – Medium
A42: A6-4 | B42: Cart A – Medium
...

Sheet Parts
A1: Part name | B1: Category | C1: In bin(s) | D1: Bins | E1: Part numbers
A2: 1x2 Beam | B2: Beams & Plates | C2: {=TEXTJOIN(", ",TRUE,IF((Bins!$D$2:$D$179=A2)+(Bins!$E$2:$E$179=A2)+(Bins!$F$2:$F$179=A2)+(Bins!$G$2:$G$179=A2)+(Bins!$H$2:$H$179=A2),Bins!$A$2:$A$179,""))} | D2: =COUNTIF(Bins!$D$2:$H$179,A2) | E2: 228-2500-001
A3: 2x Pitch Shaft | B3: Shafts & Rotation | C3: {=TEXTJOIN(", ",TRUE,IF((Bins!$D$2:$D$179=A3)+(Bins!$E$2:$E$179=A3)+(Bins!$F$2:$F$179=A3)+(Bins!$G$2:$G$179=A3)+(Bins!$H$2:$H$179=A3),Bins!$A$2:$A$179,""))} | D3: =COUNTIF(Bins!$D$2:$H$179,A3) | E3: 228-2500-117
A4: 1x4 Beam | B4: Beams & Plates | C4: {=TEXTJOIN(", ",TRUE,IF((Bins!$D$2:$D$179=A4)+(Bins!$E$2:$E$179=A4)+(Bins!$F$2:$F$179=A4)+(Bins!$G$2:$G$179=A4)+(Bins!$H$2:$H$179=A4),Bins!$A$2:$A$179,""))} | D4: =COUNTIF(Bins!$D$2:$H$179,A4) | E4: 228-2500-003, 228-3616-003
A5: 4x Pitch Shaft | B5: Shafts & Rotation | C5: {=TEXTJOIN(", ",TRUE,IF((Bins!$D$2:$D$179=A5)+(Bins!$E$2:$E$179=A5)+(Bins!$F$2:$F$179=A5)+(Bins!$G$2:$G$179=A5)+(Bins!$H$2:$H$179=A5),Bins!$A$2:$A$179,""))} | D5: =COUNTIF(Bins!$D$2:$H$179,A5) | E5: 228-2500-120
A6: 1x6 Beam | B6: Beams & Plates | C6: {=TEXTJOIN(", ",TRUE,IF((Bins!$D$2:$D$179=A6)+(Bins!$E$2:$E$179=A6)+(Bins!$F$2:$F$179=A6)+(Bins!$G$2:$G$179=A6)+(Bins!$H$2:$H$179=A6),Bins!$A$2:$A$179,""))} | D6: =COUNTIF(Bins!$D$2:$H$179,A6) | E6: 228-2500-005, 228-3616-005
A7: 6x Pitch Shaft | B7: Shafts & Rotation | C7: {=TEXTJOIN(", ",TRUE,IF((Bins!$D$2:$D$179=A7)+(Bins!$E$2:$E$179=A7)+(Bins!$F$2:$F$179=A7)+(Bins!$G$2:$G$179=A7)+(Bins!$H$2:$H$179=A7),Bins!$A$2:$A$179,""))} | D7: =COUNTIF(Bins!$D$2:$H$179,A7) | E7: 228-2500-122
A8: 1x8 Beam | B8: Beams & Plates | C8: {=TEXTJOIN(", ",TRUE,IF((Bins!$D$2:$D$179=A8)+(Bins!$E$2:$E$179=A8)+(Bins!$F$2:$F$179=A8)+(Bins!$G$2:$G$179=A8)+(Bins!$H$2:$H$179=A8),Bins!$A$2:$A$179,""))} | D8: =COUNTIF(Bins!$D$2:$H$179,A8) | E8: 228-2500-007, 228-3616-007
A9: 8x Pitch Shaft | B9: Shafts & Rotation | C9: {=TEXTJOIN(", ",TRUE,IF((Bins!$D$2:$D$179=A9)+(Bins!$E$2:$E$179=A9)+(Bins!$F$2:$F$179=A9)+(Bins!$G$2:$G$179=A9)+(Bins!$H$2:$H$179=A9),Bins!$A$2:$A$179,""))} | D9: =COUNTIF(Bins!$D$2:$H$179,A9) | E9: 228-2500-124
A10: 1x10 Beam | B10: Beams & Plates | C10: {=TEXTJOIN(", ",TRUE,IF((Bins!$D$2:$D$179=A10)+(Bins!$E$2:$E$179=A10)+(Bins!$F$2:$F$179=A10)+(Bins!$G$2:$G$179=A10)+(Bins!$H$2:$H$179=A10),Bins!$A$2:$A$179,""))} | D10: =COUNTIF(Bins!$D$2:$H$179,A10) | E10: 228-2500-009, 228-3616-009
A11: 2x10 Beam | B11: Beams & Plates | C11: {=TEXTJOIN(", ",TRUE,IF((Bins!$D$2:$D$179=A11)+(Bins!$E$2:$E$179=A11)+(Bins!$F$2:$F$179=A11)+(Bins!$G$2:$G$179=A11)+(Bins!$H$2:$H$179=A11),Bins!$A$2:$A$179,""))} | D11: =COUNTIF(Bins!$D$2:$H$179,A11) | E11: 228-2500-025, 228-3616-025
A12: 2x2 Beam | B12: Beams & Plates | C12: {=TEXTJOIN(", ",TRUE,IF((Bins!$D$2:$D$179=A12)+(Bins!$E$2:$E$179=A12)+(Bins!$F$2:$F$179=A12)+(Bins!$G$2:$G$179=A12)+(Bins!$H$2:$H$179=A12),Bins!$A$2:$A$179,""))} | D12: =COUNTIF(Bins!$D$2:$H$179,A12) | E12: 228-2500-017, 228-3616-017
A13: 2x4 Beam | B13: Beams & Plates | C13: {=TEXTJOIN(", ",TRUE,IF((Bins!$D$2:$D$179=A13)+(Bins!$E$2:$E$179=A13)+(Bins!$F$2:$F$179=A13)+(Bins!$G$2:$G$179=A13)+(Bins!$H$2:$H$179=A13),Bins!$A$2:$A$179,""))} | D13: =COUNTIF(Bins!$D$2:$H$179,A13) | E13: 228-2500-019, 228-3616-019
... A163: 1x Pitch Linear Motion Bracket (Snap Mount) | B163: Linear Motion | C163: {=TEXTJOIN(", ",TRUE,IF((Bins!$D$2:$D$179=A163)+(Bins!$E$2:$E$179=A163)+(Bins!$F$2:$F$179=A163)+(Bins!$G$2:$G$179=A163)+(Bins!$H$2:$H$179=A163),Bins!$A$2:$A$179,""))} | D163: =COUNTIF(Bins!$D$2:$H$179,A163) | E163: 228-2500-1470

Sheet How to use
A1: Bin assignments — editing sheet for data/parts.json
A3: Bins tab: one row per bin. Type in a Part column; Excel suggests matching part names (arrow keys + Enter to pick).
A4: Bin Label: what the bin's label/website should say. Leave blank to use the part names.
A5: To move a part: delete it from its old bin and type it into the new one.
A6: A part can go in more than one bin (high-volume parts): type it in each bin. The first bin is its main one.
A7: Light blue cell = that part is in more than one bin — check it's on purpose. Parts tab: red = not placed anywhere.
A8: Parts that share a bin should share one Bin Label; a part split across bins uses the first bin's label.
A10: When done: save, then run python3 tools/apply_bin_sheet.py (preview)
A11: and python3 tools/apply_bin_sheet.py --apply (writes data/parts.json).
A13: Sheet is generated from parts.json by tools/make_bin_sheet.py — regenerating overwrites unapplied edits.
